Workbook

Sheet Cover
B3: Assignment
B4: DLF Limited × Awfis Space Solutions Limited
B5: M&A Valuation & Accretion/Dilution Model
B7: STRATEGIC RATIONALE
B8: • Vertical integration: DLF (India's largest commercial real estate developer) acquiring Awfis
B9: (India's largest listed flexible workspace operator) creates an end-to-end 'build-to-flex' platform
B10: • Captive demand: DLF's ~44 msf commercial portfolio gains a ready operator for underutilized floors
B11: • Yield enhancement: Flex workspace generates 1.8–2.2x the rental yield of bare-shell leasing
B12: • Cross-sell: DLF's corporate tenant base (Fortune 500 occupiers) seeded directly to Awfis
B13: • Hedge against cyclical residential: Awfis adds a recurring-revenue, annuity-style income stream
B15: TRANSACTION SNAPSHOT
B16: Acquirer | C16: DLF Limited (NSE: DLF)
B17: Target | C17: Awfis Space Solutions Ltd (NSE: AWFIS)
B18: Deal Date (assumed) | C18: 10-Apr-2026
B19: Transaction Type | C19: Public-to-Public Acquisition (100% stake)
B20: Consideration | C20: Multiple scenarios: All Cash / All Stock / Mixed (50/50 Cash-Debt/Stock)
B21: Accounting | C21: Ind AS 103 — Business Combinations (Purchase Method)
B22: Regulatory | C22: SEBI Takeover Code, CCI approval, Stock Exchange approvals
B23: Currency | C23: All figures in INR Crores unless stated otherwise
B25: WORKBOOK CONTENTS
B26: 1. Cover | C26: This page — deal overview
B27: 2. Assumptions | C27: All key inputs with rationale & sources
B28: 3. Acquirer_Financials | C28: DLF historical P&L, B/S, CF (FY23–FY26E)
B29: 4. Target_Financials | C29: Awfis historical P&L, B/S, CF (FY23–FY26E)
B30: 5. DCF | C30: Discounted cash flow valuation of Awfis
B31: 6. Trading_Comps | C31: Listed peer multiples-based valuation
B32: 7. Precedent_Transactions | C32: M&A transaction multiples-based valuation
B33: 8. Football_Field | C33: Valuation range summary chart
B34: 9. Accretion_Dilution | C34: Pro forma EPS impact — 3 financing scenarios
B35: 10. Sensitivity | C35: Offer price × stock-mix sensitivity tables
B36: 11. Summary | C36: Recommendation & deal thesis
B39: FORMATTING LEGEND
B40: Blue text | C40: Hardcoded input (change these to run scenarios)
B41: Black text | C41: Formula / calculation within sheet
B42: Green text | C42: Link pulling from another sheet
B43: Yellow fill | C43: Key assumption cell — tweak to sensitize output

Sheet Assumptions
B2: KEY ASSUMPTIONS
B3: All inputs with rationale, sources, and benchmarks
B5: Assumption | C5: Value | D5: Unit | E5: Rationale / Source
B6: 1. MARKET DATA (as of 8-Apr-2026)
B7: DLF — Share Price (CMP) | C7: 568.25 | D7: INR | E7: NSE closing price, 8-Apr-2026 (Kotak/Bajaj sources)
B8: DLF — Shares Outstanding (diluted) | C8: 247.5 | D8: Cr shares | E8: Market Cap ₹1,40,737 Cr / CMP (Screener, FY26)
B9: DLF — Market Capitalisation | C9: =C7*C8 -> 140641.88 | D9: ₹ Cr | E9: → price × Shares (calc)
B10: DLF — Net Debt (FY26E) | C10: 3500 | D10: ₹ Cr | E10: Gross debt ~₹5,000 Cr less cash ~₹1,500 Cr (FY26 est)
B11: DLF — Enterprise Value | C11: =C9+C10 -> 144141.88 | D11: ₹ Cr | E11: → mkt cap + net debt (calc)
B12: DLF — 52-Week High | C12: 886.8 | D12: INR | E12: NSE 52-week high
B13: DLF — 52-Week Low | C13: 489.4 | D13: INR | E13: NSE 52-week low
B14: DLF — Beta (5Y) | C14: 0.95 | D14: x | E14: Yahoo Finance 5Y monthly beta ~0.33–1.1; mid-case 0.95
B15: DLF — Credit Rating | C15: CRISIL AA | D15: — | E15: DLF Cyber City long-term rating (CRISIL, 2025)
B17: Awfis — Share Price (CMP) | C17: 331.05 | D17: INR | E17: NSE closing price, Feb-2026 (IndMoney/Tickertape)
B18: Awfis — Shares Outstanding (diluted) | C18: 7.2 | D18: Cr shares | E18: Market Cap ~₹2,308 Cr / CMP ~₹320 (FY26)
B19: Awfis — Market Capitalisation | C19: =C17*C18 -> 2383.56 | D19: ₹ Cr | E19: → price × Shares (calc)
B20: Awfis — Net Debt (FY26E) | C20: 1160 | D20: ₹ Cr | E20: Lease liabilities (Ind AS 116) dominate; EV-MCap gap per Yahoo
B21: Awfis — Enterprise Value | C21: =C19+C20 -> 3543.56 | D21: ₹ Cr | E21: → mkt cap + net debt (calc)
B22: Awfis — 52-Week High | C22: 718.95 | D22: INR | E22: NSE 52-week high
B23: Awfis — 52-Week Low | C23: 320.7 | D23: INR | E23: NSE 52-week low
B24: Awfis — Beta | C24: 1.2 | D24: x | E24: High-growth small-cap proxy; peers 1.1–1.3
B26: 2. DCF ASSUMPTIONS — TARGET (Awfis)
B27: Forecast Horizon | C27: 5 | D27: years | E27: Standard IB horizon (FY27E–FY31E)
B28: Risk-Free Rate (India 10Y G-Sec) | C28: 0.07 | D28: % | E28: India 10Y G-Sec ~7.0% (Apr-2026, Trading Economics)
B29: Equity Risk Premium (India) | C29: 0.075 | D29: % | E29: Damodaran India ERP (Jan 2026 update)
B30: Awfis Beta (levered) | C30: 1.2 | D30: x | E30: Same as market data section
B31: Cost of Equity (Ke) | C31: =C28+C30*C29 -> 0.16 | D31: % | E31: → rf + β × ERP (CAPM)
B32: Pre-tax Cost of Debt (Kd) | C32: 0.0925 | D32: % | E32: Awfis WACD; mid-rated NBFC/corp debt ~9.0–9.5%
B33: Effective Tax Rate | C33: 0.252 | D33: % | E33: India corporate tax rate (new regime, 25.17%)
B34: After-tax Cost of Debt | C34: =C32*(1-C33) -> 0.06919 | D34: % | E34: → kd × (1 - Tax)
B35: Debt Weight (Target capital structure) | C35: 0.4 | D35: % | E35: Awfis current D/(D+E) ~40% incl. lease liab
B36: Equity Weight | C36: =1-C35 -> 0.6 | D36: % | E36: → 1 - debt weight
B37: WACC | C37: =C36*C31+C35*C32*(1-C33) -> 0.123676 | D37: % | E37: → we×Ke + Wd×Kd×(1-T)
B39: Revenue Growth Y1 (FY27E) | C39: 0.28 | D39: % | E39: Mgmt guidance ~25–30%; flex market CAGR 20–25%
B40: Revenue Growth Y2 (FY28E) | C40: 0.24 | D40: % | E40: Step-down as base effect kicks in
B41: Revenue Growth Y3 (FY29E) | C41: 0.2 | D41: % | E41: Maturing growth phase
B42: Revenue Growth Y4 (FY30E) | C42: 0.16 | D42: % | E42: Gradual convergence
B43: Revenue Growth Y5 (FY31E) | C43: 0.12 | D43: % | E43: Terminal approach
B44: EBITDA Margin (steady-state) | C44: 0.28 | D44: % | E44: Awfis LTM margin ~33–36%, Ind AS 116 inflated
B45: D&A as % of Revenue | C45: 0.22 | D45: % | E45: Heavy fitout amort + ROU asset amort
...

Sheet Acquirer_Financials
B2: DLF LIMITED — FINANCIAL SUMMARY
B3: Historical + projected, consolidated, ₹ Crores
B5: Particulars | C5: FY23A | D5: FY24A | E5: FY25A | F5: FY26E | G5: FY27E | H5: FY28E | I5: FY29E
B6: INCOME STATEMENT
B7: Revenue from Operations | C7: 5695 | D7: 6427 | E7: 8996 | F7: 10800 | G7: 12960 | H7: 15000 | I7: 16800
B8: Growth % | D8: =D7/C7-1 -> 0.1285338 | E8: =E7/D7-1 -> 0.39971993 | F8: =F7/E7-1 -> 0.20053357 | G8: =G7/F7-1 -> 0.2 | H8: =H7/G7-1 -> 0.15740741 | I8: =I7/H7-1 -> 0.12
B9: EBITDA | C9: 1878 | D9: 2313 | E9: 3598 | F9: 4320 | G9: 5313 | H9: 6150 | I9: 6888
B10: EBITDA Margin % | C10: =C9/C7 -> 0.32976295 | D10: =D9/D7 -> 0.35988797 | E10: =E9/E7 -> 0.39995554 | F10: =F9/F7 -> 0.4 | G10: =G9/G7 -> 0.4099537 | H10: =H9/H7 -> 0.41 | I10: =I9/I7 -> 0.41
B11: (-) Depreciation & Amortisation | C11: 250 | D11: 280 | E11: 320 | F11: 350 | G11: 390 | H11: 430 | I11: 475
B12: EBIT | C12: =C9-C11 -> 1628 | D12: =D9-D11 -> 2033 | E12: =E9-E11 -> 3278 | F12: =F9-F11 -> 3970 | G12: =G9-G11 -> 4923 | H12: =H9-H11 -> 5720 | I12: =I9-I11 -> 6413
B13: (-) Interest Expense | C13: 280 | D13: 250 | E13: 220 | F13: 195 | G13: 180 | H13: 170 | I13: 160
B14: (+) Other Income | C14: 550 | D14: 620 | E14: 680 | F14: 720 | G14: 780 | H14: 840 | I14: 900
B15: Profit Before Tax | C15: =C12-C13+C14 -> 1898 | D15: =D12-D13+D14 -> 2403 | E15: =E12-E13+E14 -> 3738 | F15: =F12-F13+F14 -> 4495 | G15: =G12-G13+G14 -> 5523 | H15: =H12-H13+H14 -> 6390 | I15: =I12-I13+I14 -> 7153
B16: (-) Tax | C16: =C15*0.252 -> 478.296 | D16: =D15*0.252 -> 605.556 | E16: =E15*0.252 -> 941.976 | F16: =F15*0.252 -> 1132.74 | G16: =G15*0.252 -> 1391.796 | H16: =H15*0.252 -> 1610.28 | I16: =I15*0.252 -> 1802.556
B17: PAT (Net Income) | C17: =C15-C16 -> 1419.704 | D17: =D15-D16 -> 1797.444 | E17: =E15-E16 -> 2796.024 | F17: =F15-F16 -> 3362.26 | G17: =G15-G16 -> 4131.204 | H17: =H15-H16 -> 4779.72 | I17: =I15-I16 -> 5350.444
B18: Diluted Shares Outstanding (Cr) | C18: 247.5 | D18: 247.5 | E18: 247.5 | F18: 247.5 | G18: 247.5 | H18: 247.5 | I18: 247.5
B19: EPS (₹) | C19: =C17/C18 -> 5.7361778 | D19: =D17/D18 -> 7.2624 | E19: =E17/E18 -> 11.297067 | F19: =F17/F18 -> 13.584889 | G19: =G17/G18 -> 16.691733 | H19: =H17/H18 -> 19.312 | I19: =I17/I18 -> 21.617956
B21: BALANCE SHEET — KEY ITEMS
B22: Total Debt | C22: 5500 | D22: 5300 | E22: 5100 | F22: 5000 | G22: 4800 | H22: 4600 | I22: 4400
B23: Cash & Equivalents | C23: 1200 | D23: 1400 | E23: 1350 | F23: 1500 | G23: 1650 | H23: 1800 | I23: 1950
B24: Net Debt | C24: =C22-C23 -> 4300 | D24: =D22-D23 -> 3900 | E24: =E22-E23 -> 3750 | F24: =F22-F23 -> 3500 | G24: =G22-G23 -> 3150 | H24: =H22-H23 -> 2800 | I24: =I22-I23 -> 2450
B25: Total Equity | C25: 36500 | D25: 38200 | E25: 40500 | F25: 42800 | G25: 45600 | H25: 48900 | I25: 52800
B27: Source: DLF Annual Reports FY23-FY25, Screener.in consolidated data, management guidance.
B28: FY26E onwards: author estimates based on sales bookings trajectory and historical margin trends.

Sheet Target_Financials
B2: AWFIS SPACE SOLUTIONS — FINANCIAL SUMMARY
B3: Historical + projected, consolidated, ₹ Crores
B5: Particulars | C5: FY23A | D5: FY24A | E5: FY25A | F5: FY26E | G5: FY27E | H5: FY28E | I5: FY29E
B6: INCOME STATEMENT
B7: Revenue from Operations | C7: 545 | D7: 849 | E7: 1208 | F7: 1500 | G7: 1920 | H7: 2381 | I7: 2857
B8: Growth % | D8: =D7/C7-1 -> 0.55779817 | E8: =E7/D7-1 -> 0.42285041 | F8: =F7/E7-1 -> 0.24172185 | G8: =G7/F7-1 -> 0.28 | H8: =H7/G7-1 -> 0.24010417 | I8: =I7/H7-1 -> 0.199916
B9: EBITDA | C9: 166 | D9: 279 | E9: 425 | F9: 510 | G9: 653 | H9: 810 | I9: 972
B10: EBITDA Margin % | C10: =C9/C7 -> 0.30458716 | D10: =D9/D7 -> 0.32862191 | E10: =E9/E7 -> 0.35182119 | F10: =F9/F7 -> 0.34 | G10: =G9/G7 -> 0.34010417 | H10: =H9/H7 -> 0.3401932 | I10: =I9/I7 -> 0.34021701
B11: (-) D&A (incl. ROU amort) | C11: 120 | D11: 195 | E11: 290 | F11: 345 | G11: 422 | H11: 524 | I11: 628
B12: EBIT | C12: =C9-C11 -> 46 | D12: =D9-D11 -> 84 | E12: =E9-E11 -> 135 | F12: =F9-F11 -> 165 | G12: =G9-G11 -> 231 | H12: =H9-H11 -> 286 | I12: =I9-I11 -> 344
B13: (-) Interest Expense (incl. lease) | C13: 58 | D13: 75 | E13: 95 | F13: 115 | G13: 140 | H13: 165 | I13: 190
B14: (+) Other Income | C14: 12 | D14: 18 | E14: 25 | F14: 30 | G14: 35 | H14: 40 | I14: 45
B15: Profit Before Tax | C15: =C12-C13+C14 -> 0 | D15: =D12-D13+D14 -> 27 | E15: =E12-E13+E14 -> 65 | F15: =F12-F13+F14 -> 80 | G15: =G12-G13+G14 -> 126 | H15: =H12-H13+H14 -> 161 | I15: =I12-I13+I14 -> 199
B16: (-) Tax | C16: =MAX(C15*0.252,0) -> 0 | D16: =MAX(D15*0.252,0) -> 6.804 | E16: =MAX(E15*0.252,0) -> 16.38 | F16: =MAX(F15*0.252,0) -> 20.16 | G16: =MAX(G15*0.252,0) -> 31.752 | H16: =MAX(H15*0.252,0) -> 40.572 | I16: =MAX(I15*0.252,0) -> 50.148
B17: PAT (Net Income) | C17: =C15-C16 -> 0 | D17: =D15-D16 -> 20.196 | E17: =E15-E16 -> 48.62 | F17: =F15-F16 -> 59.84 | G17: =G15-G16 -> 94.248 | H17: =H15-H16 -> 120.428 | I17: =I15-I16 -> 148.852
B18: Diluted Shares Outstanding (Cr) | C18: 7.2 | D18: 7.2 | E18: 7.2 | F18: 7.2 | G18: 7.2 | H18: 7.2 | I18: 7.2
B19: EPS (₹) | C19: =C17/C18 -> 0 | D19: =D17/D18 -> 2.805 | E19: =E17/E18 -> 6.7527778 | F19: =F17/F18 -> 8.3111111 | G19: =G17/G18 -> 13.09 | H19: =H17/H18 -> 16.726111 | I19: =I17/I18 -> 20.673889
B21: BALANCE SHEET — KEY ITEMS
B22: Total Debt (incl. lease liab) | C22: 620 | D22: 950 | E22: 1250 | F22: 1460 | G22: 1700 | H22: 1950 | I22: 2200
B23: Cash & Equivalents | C23: 150 | D23: 180 | E23: 260 | F23: 300 | G23: 340 | H23: 380 | I23: 420
B24: Net Debt | C24: =C22-C23 -> 470 | D24: =D22-D23 -> 770 | E24: =E22-E23 -> 990 | F24: =F22-F23 -> 1160 | G24: =G22-G23 -> 1360 | H24: =H22-H23 -> 1570 | I24: =I22-I23 -> 1780
B25: Total Equity | C25: 340 | D25: 460 | E25: 540 | F25: 620 | G25: 730 | H25: 865 | I25: 1025
B27: Source: Awfis Annual Reports FY23–FY25, Screener.in, Q2/Q3 FY26 results (Tickertape, BSE).
B28: FY26E onwards: author estimates based on seat additions guidance (247 centers, 170k seats).

Sheet Ratio_Analysis
B2: RATIO ANALYSIS — DLF & AWFIS
B3: 4-year historical trend + peer benchmark | All values computed live from Financial sheets
B5: Ratio | C5: DLF (Acquirer) | H5: Awfis (Target) | M5: Peer Benchmark
C6: FY23A | D6: FY24A | E6: FY25A | F6: FY26E | H6: FY23A | I6: FY24A | J6: FY25A | K6: FY26E | M6: Sector Median | N6: Commentary
B7: 1. PROFITABILITY RATIOS
B8: EBITDA Margin | C8: =Acquirer_Financials!C9/Acquirer_Financials!C7 -> 0.32976295 | D8: =Acquirer_Financials!D9/Acquirer_Financials!D7 -> 0.35988797 | E8: =Acquirer_Financials!E9/Acquirer_Financials!E7 -> 0.39995554 | F8: =Acquirer_Financials!F9/Acquirer_Financials!F7 -> 0.4 | H8: =Target_Financials!C9/Target_Financials!C7 -> 0.30458716 | I8: =Target_Financials!D9/Target_Financials!D7 -> 0.32862191 | J8: =Target_Financials!E9/Target_Financials!E7 -> 0.35182119 | K8: =Target_Financials!F9/Target_Financials!F7 -> 0.34 | M8: 0.32 | N8: DLF ~40% vs sector ~32%; Awfis ~34% (Ind AS 116 lease inflation)
B9: EBIT Margin | C9: =Acquirer_Financials!C12/Acquirer_Financials!C7 -> 0.28586479 | D9: =Acquirer_Financials!D12/Acquirer_Financials!D7 -> 0.31632177 | E9: =Acquirer_Financials!E12/Acquirer_Financials!E7 -> 0.36438417 | F9: =Acquirer_Financials!F12/Acquirer_Financials!F7 -> 0.36759259 | H9: =Target_Financials!C12/Target_Financials!C7 -> 0.08440367 | I9: =Target_Financials!D12/Target_Financials!D7 -> 0.098939929 | J9: =Target_Financials!E12/Target_Financials!E7 -> 0.11175497 | K9: =Target_Financials!F12/Target_Financials!F7 -> 0.11 | M9: 0.24 | N9: DLF margins expanding; Awfis thin on EBIT due to high D&A
B10: Net Profit Margin | C10: =Acquirer_Financials!C17/Acquirer_Financials!C7 -> 0.24928955 | D10: =Acquirer_Financials!D17/Acquirer_Financials!D7 -> 0.27967076 | E10: =Acquirer_Financials!E17/Acquirer_Financials!E7 -> 0.31080747 | F10: =Acquirer_Financials!F17/Acquirer_Financials!F7 -> 0.31132037 | H10: =Target_Financials!C17/Target_Financials!C7 -> 0 | I10: =Target_Financials!D17/Target_Financials!D7 -> 0.023787986 | J10: =Target_Financials!E17/Target_Financials!E7 -> 0.040248344 | K10: =Target_Financials!F17/Target_Financials!F7 -> 0.039893333 | M10: 0.18 | N10: DLF 30%+ (luxury residential mix); Awfis 3-5% (recent profitability)
B11: Return on Equity (ROE) | C11: =Acquirer_Financials!C17/Acquirer_Financials!C25 -> 0.038896 | D11: =Acquirer_Financials!D17/Acquirer_Financials!D25 -> 0.047053508 | E11: =Acquirer_Financials!E17/Acquirer_Financials!E25 -> 0.06903763 | F11: =Acquirer_Financials!F17/Acquirer_Financials!F25 -> 0.078557477 | H11: =Target_Financials!C17/Target_Financials!C25 -> 0 | I11: =Target_Financials!D17/Target_Financials!D25 -> 0.043904348 | J11: =Target_Financials!E17/Target_Financials!E25 -> 0.090037037 | K11: =Target_Financials!F17/Target_Financials!F25 -> 0.096516129 | M11: 0.12 | N11: DLF low ROE due to large equity base (inventory-heavy); Awfis improving
B12: Return on Capital Employed | C12: =Acquirer_Financials!C12/(Acquirer_Financials!C25+Acquirer_Financials!C22) -> 0.038761905 | D12: =Acquirer_Financials!D12/(Acquirer_Financials!D25+Acquirer_Financials!D22) -> 0.046735632 | E12: =Acquirer_Financials!E12/(Acquirer_Financials!E25+Acquirer_Financials!E22) -> 0.071885965 | F12: =Acquirer_Financials!F12/(Acquirer_Financials!F25+Acquirer_Financials!F22) -> 0.083054393 | H12: =Target_Financials!C12/(Target_Financials!C25+Target_Financials!C22) -> 0.047916667 | I12: =Target_Financials!D12/(Target_Financials!D25+Target_Financials!D22) -> 0.059574468 | J12: =Target_Financials!E12/(Target_Financials!E25+Target_Financials!E22) -> 0.075418994 | K12: =Target_Financials!F12/(Target_Financials!F25+Target_Financials!F22) -> 0.079326923 | M12: 0.11 | N12: DLF ROCE improving as asset turnover rises
B14: 2. LIQUIDITY RATIOS
B15: Cash Ratio (Cash / Total Debt) | C15: =Acquirer_Financials!C23/Acquirer_Financials!C22 -> 0.21818182 | D15: =Acquirer_Financials!D23/Acquirer_Financials!D22 -> 0.26415094 | E15: =Acquirer_Financials!E23/Acquirer_Financials!E22 -> 0.26470588 | F15: =Acquirer_Financials!F23/Acquirer_Financials!F22 -> 0.3 | H15: =Target_Financials!C23/Target_Financials!C22 -> 0.24193548 | I15: =Target_Financials!D23/Target_Financials!D22 -> 0.18947368 | J15: =Target_Financials!E23/Target_Financials!E22 -> 0.208 | K15: =Target_Financials!F23/Target_Financials!F22 -> 0.20547945 | M15: 0.25 | N15: Proxy for liquidity; DLF maintains ~25-30% cash against debt
B16: Interest Coverage (EBIT/Interest) | C16: =Acquirer_Financials!C12/Acquirer_Financials!C13 -> 5.8142857 | D16: =Acquirer_Financials!D12/Acquirer_Financials!D13 -> 8.132 | E16: =Acquirer_Financials!E12/Acquirer_Financials!E13 -> 14.9 | F16: =Acquirer_Financials!F12/Acquirer_Financials!F13 -> 20.358974 | H16: =Target_Financials!C12/Target_Financials!C13 -> 0.79310345 | I16: =Target_Financials!D12/Target_Financials!D13 -> 1.12 | J16: =Target_Financials!E12/Target_Financials!E13 -> 1.4210526 | K16: =Target_Financials!F12/Target_Financials!F13 -> 1.4347826 | M16: 4.5 | N16: DLF very comfortable (>10x); Awfis tight (~1.5-2x) due to lease interest
B17: Interest Coverage (EBITDA/Interest) | C17: =Acquirer_Financials!C9/Acquirer_Financials!C13 -> 6.7071429 | D17: =Acquirer_Financials!D9/Acquirer_Financials!D13 -> 9.252 | E17: =Acquirer_Financials!E9/Acquirer_Financials!E13 -> 16.354545 | F17: =Acquirer_Financials!F9/Acquirer_Financials!F13 -> 22.153846 | H17: =Target_Financials!C9/Target_Financials!C13 -> 2.862069 | I17: =Target_Financials!D9/Target_Financials!D13 -> 3.72 | J17: =Target_Financials!E9/Target_Financials!E13 -> 4.4736842 | K17: =Target_Financials!F9/Target_Financials!F13 -> 4.4347826 | M17: 6 | N17: Softer metric; both well-covered on EBITDA basis
B19: 3. SOLVENCY / LEVERAGE RATIOS
B20: Debt-to-Equity | C20: =Acquirer_Financials!C22/Acquirer_Financials!C25 -> 0.15068493 | D20: =Acquirer_Financials!D22/Acquirer_Financials!D25 -> 0.13874346 | E20: =Acquirer_Financials!E22/Acquirer_Financials!E25 -> 0.12592593 | F20: =Acquirer_Financials!F22/Acquirer_Financials!F25 -> 0.11682243 | H20: =Target_Financials!C22/Target_Financials!C25 -> 1.8235294 | I20: =Target_Financials!D22/Target_Financials!D25 -> 2.0652174 | J20: =Target_Financials!E22/Target_Financials!E25 -> 2.3148148 | K20: =Target_Financials!F22/Target_Financials!F25 -> 2.3548387 | M20: 0.6 | N20: DLF very conservative (~0.12x); Awfis elevated (~2x incl. lease liab)
B21: Net Debt / Equity | C21: =Acquirer_Financials!C24/Acquirer_Financials!C25 -> 0.11780822 | D21: =Acquirer_Financials!D24/Acquirer_Financials!D25 -> 0.10209424 | E21: =Acquirer_Financials!E24/Acquirer_Financials!E25 -> 0.092592593 | F21: =Acquirer_Financials!F24/Acquirer_Financials!F25 -> 0.081775701 | H21: =Target_Financials!C24/Target_Financials!C25 -> 1.3823529 | I21: =Target_Financials!D24/Target_Financials!D25 -> 1.673913 | J21: =Target_Financials!E24/Target_Financials!E25 -> 1.8333333 | K21: =Target_Financials!F24/Target_Financials!F25 -> 1.8709677 | M21: 0.45 | N21: DLF near-net-cash profile; Awfis leveraged
B22: Net Debt / EBITDA | C22: =Acquirer_Financials!C24/Acquirer_Financials!C9 -> 2.2896699 | D22: =Acquirer_Financials!D24/Acquirer_Financials!D9 -> 1.6861219 | E22: =Acquirer_Financials!E24/Acquirer_Financials!E9 -> 1.0422457 | F22: =Acquirer_Financials!F24/Acquirer_Financials!F9 -> 0.81018519 | H22: =Target_Financials!C24/Target_Financials!C9 -> 2.8313253 | I22: =Target_Financials!D24/Target_Financials!D9 -> 2.7598566 | J22: =Target_Financials!E24/Target_Financials!E9 -> 2.3294118 | K22: =Target_Financials!F24/Target_Financials!F9 -> 2.2745098 | M22: 2.2 | N22: DLF <1x (investment-grade); Awfis ~2.3x (reasonable for flex-op)
B23: Debt / Total Assets (proxy) | C23: =Acquirer_Financials!C22/(Acquirer_Financials!C22+Acquirer_Financials!C25) -> 0.13095238 | D23: =Acquirer_Financials!D22/(Acquirer_Financials!D22+Acquirer_Financials!D25) -> 0.12183908 | E23: =Acquirer_Financials!E22/(Acquirer_Financials!E22+Acquirer_Financials!E25) -> 0.11184211 | F23: =Acquirer_Financials!F22/(Acquirer_Financials!F22+Acquirer_Financials!F25) -> 0.10460251 | H23: =Target_Financials!C22/(Target_Financials!C22+Target_Financials!C25) -> 0.64583333 | I23: =Target_Financials!D22/(Target_Financials!D22+Target_Financials!D25) -> 0.67375887 | J23: =Target_Financials!E22/(Target_Financials!E22+Target_Financials!E25) -> 0.69832402 | K23: =Target_Financials!F22/(Target_Financials!F22+Target_Financials!F25) -> 0.70192308 | M23: 0.38 | N23: DLF asset-light on debt; Awfis 65-70% levered
B25: 4. EFFICIENCY / TURNOVER RATIOS
B26: Asset Turnover (Rev/Total Capital) | C26: =Acquirer_Financials!C7/(Acquirer_Financials!C22+Acquirer_Financials!C25) -> 0.13559524 | D26: =Acquirer_Financials!D7/(Acquirer_Financials!D22+Acquirer_Financials!D25) -> 0.14774713 | E26: =Acquirer_Financials!E7/(Acquirer_Financials!E22+Acquirer_Financials!E25) -> 0.1972807 | F26: =Acquirer_Financials!F7/(Acquirer_Financials!F22+Acquirer_Financials!F25) -> 0.22594142 | H26: =Target_Financials!C7/(Target_Financials!C22+Target_Financials!C25) -> 0.56770833 | I26: =Target_Financials!D7/(Target_Financials!D22+Target_Financials!D25) -> 0.60212766 | J26: =Target_Financials!E7/(Target_Financials!E22+Target_Financials!E25) -> 0.67486034 | K26: =Target_Financials!F7/(Target_Financials!F22+Target_Financials!F25) -> 0.72115385 | M26: 0.35 | N26: Awfis higher turnover (flex-op is capital-light vs land banking)
B27: Equity Turnover (Rev/Equity) | C27: =Acquirer_Financials!C7/Acquirer_Financials!C25 -> 0.1560274 | D27: =Acquirer_Financials!D7/Acquirer_Financials!D25 -> 0.16824607 | E27: =Acquirer_Financials!E7/Acquirer_Financials!E25 -> 0.22212346 | F27: =Acquirer_Financials!F7/Acquirer_Financials!F25 -> 0.25233645 | H27: =Target_Financials!C7/Target_Financials!C25 -> 1.6029412 | I27: =Target_Financials!D7/Target_Financials!D25 -> 1.8456522 | J27: =Target_Financials!E7/Target_Financials!E25 -> 2.237037 | K27: =Target_Financials!F7/Target_Financials!F25 -> 2.4193548 | M27: 0.5 | N27: Awfis ~2x vs DLF ~0.2x — reflects different business models
B29: 5. VALUATION RATIOS (at current CMP)
B30: P/E Ratio | C30: =Assumptions!$C$7/Acquirer_Financials!C19 -> 99.064224 | D30: =Assumptions!$C$7/Acquirer_Financials!D19 -> 78.245484 | E30: =Assumptions!$C$7/Acquirer_Financials!E19 -> 50.300668 | F30: =Assumptions!$C$7/Acquirer_Financials!F19 -> 41.829566 | H30: =IFERROR(Assumptions!$C$17/Target_Financials!C19,"N/M") -> N/M | I30: =IFERROR(Assumptions!$C$17/Target_Financials!D19,"N/M") -> 118.02139 | J30: =IFERROR(Assumptions!$C$17/Target_Financials!E19,"N/M") -> 49.02427 | K30: =IFERROR(Assumptions!$C$17/Target_Financials!F19,"N/M") -> 39.832219 | M30: 28 | N30: Real estate sector ~28-35x; Awfis at premium
B31: P/B Ratio | C31: =Assumptions!$C$9/Acquirer_Financials!C25 -> 3.8532021 | D31: =Assumptions!$C$9/Acquirer_Financials!D25 -> 3.6817245 | E31: =Assumptions!$C$9/Acquirer_Financials!E25 -> 3.4726389 | F31: =Assumptions!$C$9/Acquirer_Financials!F25 -> 3.2860251 | H31: =Assumptions!$C$19/Target_Financials!C25 -> 7.0104706 | I31: =Assumptions!$C$19/Target_Financials!D25 -> 5.1816522 | J31: =Assumptions!$C$19/Target_Financials!E25 -> 4.414 | K31: =Assumptions!$C$19/Target_Financials!F25 -> 3.8444516 | M31: 2.5 | N31: DLF ~3.1x; Awfis ~4.5x (high-growth premium)
B32: EV/EBITDA | C32: =Assumptions!$C$11/Acquirer_Financials!C9 -> 76.752862 | D32: =Assumptions!$C$11/Acquirer_Financials!D9 -> 62.318147 | E32: =Assumptions!$C$11/Acquirer_Financials!E9 -> 40.061666 | F32: =Assumptions!$C$11/Acquirer_Financials!F9 -> 33.366175 | H32: =Assumptions!$C$21/Target_Financials!C9 -> 21.346747 | I32: =Assumptions!$C$21/Target_Financials!D9 -> 12.700932 | J32: =Assumptions!$C$21/Target_Financials!E9 -> 8.3377882 | K32: =Assumptions!$C$21/Target_Financials!F9 -> 6.9481569 | M32: 17 | N32: DLF at significant discount to EBITDA mult; Awfis in-line
B33: EV/Sales | C33: =Assumptions!$C$11/Acquirer_Financials!C7 -> 25.31025 | D33: =Assumptions!$C$11/Acquirer_Financials!D7 -> 22.427552 | E33: =Assumptions!$C$11/Acquirer_Financials!E7 -> 16.022885 | F33: =Assumptions!$C$11/Acquirer_Financials!F7 -> 13.34647 | H33: =Assumptions!$C$21/Target_Financials!C7 -> 6.501945 | I33: =Assumptions!$C$21/Target_Financials!D7 -> 4.1738045 | J33: =Assumptions!$C$21/Target_Financials!E7 -> 2.9334106 | K33: =Assumptions!$C$21/Target_Financials!F7 -> 2.3623733 | M33: 5.5 | N33: DLF trading at ~16x sales (luxury premium)
B34: Dividend Yield (DLF only) | C34: 0.006 | D34: 0.007 | E34: 0.0088 | F34: 0.0117 | H34: N/A | I34: N/A | J34: N/A | K34: N/A | M34: 0.009 | N34: DLF yield rising as price fell; Awfis doesn't pay div
B37: KEY OBSERVATIONS FROM RATIO ANALYSIS
B38: DLF:
B39: • Best-in-class profitability: EBITDA margins ~40% (sector median ~32%) driven by luxury-residential mix
B40: • Conservative balance sheet: Net Debt/EBITDA <1.0x; Debt/Equity ~0.12x — significant headroom for acquisitions
B41: • Low ROE (~10-11%) reflects inventory-heavy model; land bank monetisation should improve this over FY27-30
B42: • Trading at premium P/E (~42x) and P/B (~3x) — market pricing in luxury pipeline and DLF5 completion
B43: • Strong interest coverage (>15x) and cash generation from rental arm provide deal flexibility
B45: Awfis:
B46: • Asset-light, capital-efficient model: Revenue/Equity ~2.5x vs DLF's 0.2x — validates flex-operator thesis
B47: • EBITDA margins 33-36% inflated by Ind AS 116 lease accounting; normalised EBITDA margin closer to 15-18%
B48: • Tight interest coverage (~2x EBIT basis) due to lease liabilities — suggests financing constraint
B49: • Net Debt/EBITDA ~2.3x is high for a small-cap; acquisition by DLF would de-risk capital structure
...

Sheet Price_Volume_Trends
B2: PRICE & VOLUME TREND ANALYSIS
B3: Monthly historical data, returns, volatility, key events | DLF & Awfis
B5: SECTION 1 — DLF LIMITED (NSE: DLF)
B6: Month-End | C6: Open (₹) | D6: High (₹) | E6: Low (₹) | F6: Close (₹) | G6: Volume (Lakh) | H6: Monthly Return | I6: 52W High | J6: 52W Low | K6: From 52W High | L6: From 52W Low
B7: Apr-2022 | C7: 385 | D7: 410 | E7: 370 | F7: 395 | G7: 450 | H7: — | I7: =MAX(D7:D7) -> 410 | J7: =MIN(E7:E7) -> 370 | K7: =F7/I7-1 -> -0.036585366 | L7: =F7/J7-1 -> 0.067567568
B8: Jul-2022 | C8: 350 | D8: 380 | E8: 325 | F8: 365 | G8: 520 | H8: =F8/F7-1 -> -0.075949367 | I8: =MAX(D7:D8) -> 410 | J8: =MIN(E7:E8) -> 325 | K8: =F8/I8-1 -> -0.1097561 | L8: =F8/J8-1 -> 0.12307692
B9: Oct-2022 | C9: 380 | D9: 420 | E9: 365 | F9: 405 | G9: 480 | H9: =F9/F8-1 -> 0.10958904 | I9: =MAX(D7:D9) -> 420 | J9: =MIN(E7:E9) -> 325 | K9: =F9/I9-1 -> -0.035714286 | L9: =F9/J9-1 -> 0.24615385
B10: Jan-2023 | C10: 400 | D10: 430 | E10: 375 | F10: 410 | G10: 550 | H10: =F10/F9-1 -> 0.012345679 | I10: =MAX(D7:D10) -> 430 | J10: =MIN(E7:E10) -> 325 | K10: =F10/I10-1 -> -0.046511628 | L10: =F10/J10-1 -> 0.26153846
B11: Apr-2023 | C11: 395 | D11: 480 | E11: 380 | F11: 465 | G11: 620 | H11: =F11/F10-1 -> 0.13414634 | I11: =MAX(D7:D11) -> 480 | J11: =MIN(E7:E11) -> 325 | K11: =F11/I11-1 -> -0.03125 | L11: =F11/J11-1 -> 0.43076923
B12: Jul-2023 | C12: 490 | D12: 540 | E12: 480 | F12: 520 | G12: 580 | H12: =F12/F11-1 -> 0.11827957 | I12: =MAX(D7:D12) -> 540 | J12: =MIN(E7:E12) -> 325 | K12: =F12/I12-1 -> -0.037037037 | L12: =F12/J12-1 -> 0.6
B13: Oct-2023 | C13: 530 | D13: 590 | E13: 510 | F13: 575 | G13: 640 | H13: =F13/F12-1 -> 0.10576923 | I13: =MAX(D7:D13) -> 590 | J13: =MIN(E7:E13) -> 325 | K13: =F13/I13-1 -> -0.025423729 | L13: =F13/J13-1 -> 0.76923077
B14: Jan-2024 | C14: 620 | D14: 720 | E14: 605 | F14: 690 | G14: 720 | H14: =F14/F13-1 -> 0.2 | I14: =MAX(D7:D14) -> 720 | J14: =MIN(E7:E14) -> 325 | K14: =F14/I14-1 -> -0.041666667 | L14: =F14/J14-1 -> 1.1230769
B15: Apr-2024 | C15: 880 | D15: 935 | E15: 820 | F15: 895 | G15: 850 | H15: =F15/F14-1 -> 0.29710145 | I15: =MAX(D7:D15) -> 935 | J15: =MIN(E7:E15) -> 325 | K15: =F15/I15-1 -> -0.042780749 | L15: =F15/J15-1 -> 1.7538462
B16: Jul-2024 | C16: 810 | D16: 875 | E16: 795 | F16: 830 | G16: 780 | H16: =F16/F15-1 -> -0.072625698 | I16: =MAX(D7:D16) -> 935 | J16: =MIN(E7:E16) -> 325 | K16: =F16/I16-1 -> -0.11229947 | L16: =F16/J16-1 -> 1.5538462
B17: Oct-2024 | C17: 835 | D17: 895 | E17: 820 | F17: 865 | G17: 920 | H17: =F17/F16-1 -> 0.042168675 | I17: =MAX(D7:D17) -> 935 | J17: =MIN(E7:E17) -> 325 | K17: =F17/I17-1 -> -0.07486631 | L17: =F17/J17-1 -> 1.6615385
B18: Dec-2024 | C18: 860 | D18: 897 | E18: 830 | F18: 875 | G18: 680 | H18: =F18/F17-1 -> 0.011560694 | I18: =MAX(D7:D18) -> 935 | J18: =MIN(E7:E18) -> 325 | K18: =F18/I18-1 -> -0.064171123 | L18: =F18/J18-1 -> 1.6923077
B19: Jan-2025 | C19: 850 | D19: 870 | E19: 720 | F19: 745 | G19: 730 | H19: =F19/F18-1 -> -0.14857143 | I19: =MAX(D8:D19) -> 935 | J19: =MIN(E8:E19) -> 325 | K19: =F19/I19-1 -> -0.20320856 | L19: =F19/J19-1 -> 1.2923077
B20: Feb-2025 | C20: 745 | D20: 780 | E20: 680 | F20: 715 | G20: 690 | H20: =F20/F19-1 -> -0.040268456 | I20: =MAX(D9:D20) -> 935 | J20: =MIN(E9:E20) -> 365 | K20: =F20/I20-1 -> -0.23529412 | L20: =F20/J20-1 -> 0.95890411
B21: Mar-2025 | C21: 715 | D21: 740 | E21: 645 | F21: 670 | G21: 640 | H21: =F21/F20-1 -> -0.062937063 | I21: =MAX(D10:D21) -> 935 | J21: =MIN(E10:E21) -> 375 | K21: =F21/I21-1 -> -0.28342246 | L21: =F21/J21-1 -> 0.78666667
B22: Apr-2025 | C22: 670 | D22: 695 | E22: 489 | F22: 540 | G22: 890 | H22: =F22/F21-1 -> -0.19402985 | I22: =MAX(D11:D22) -> 935 | J22: =MIN(E11:E22) -> 380 | K22: =F22/I22-1 -> -0.42245989 | L22: =F22/J22-1 -> 0.42105263
B23: Jul-2025 | C23: 625 | D23: 685 | E23: 580 | F23: 640 | G23: 550 | H23: =F23/F22-1 -> 0.18518519 | I23: =MAX(D12:D23) -> 935 | J23: =MIN(E12:E23) -> 480 | K23: =F23/I23-1 -> -0.31550802 | L23: =F23/J23-1 -> 0.33333333
B24: Oct-2025 | C24: 650 | D24: 720 | E24: 590 | F24: 680 | G24: 620 | H24: =F24/F23-1 -> 0.0625 | I24: =MAX(D13:D24) -> 935 | J24: =MIN(E13:E24) -> 489 | K24: =F24/I24-1 -> -0.27272727 | L24: =F24/J24-1 -> 0.39059305
B25: Jan-2026 | C25: 680 | D25: 765 | E25: 615 | F25: 680 | G25: 710 | H25: =F25/F24-1 -> 0 | I25: =MAX(D14:D25) -> 935 | J25: =MIN(E14:E25) -> 489 | K25: =F25/I25-1 -> -0.27272727 | L25: =F25/J25-1 -> 0.39059305
B26: Mar-2026 | C26: 620 | D26: 680 | E26: 540 | F26: 555 | G26: 580 | H26: =F26/F25-1 -> -0.18382353 | I26: =MAX(D15:D26) -> 935 | J26: =MIN(E15:E26) -> 489 | K26: =F26/I26-1 -> -0.40641711 | L26: =F26/J26-1 -> 0.13496933
B27: Apr-2026 | C27: 555 | D27: 575 | E27: 525 | F27: 568 | G27: 510 | H27: =F27/F26-1 -> 0.023423423 | I27: =MAX(D16:D27) -> 897 | J27: =MIN(E16:E27) -> 489 | K27: =F27/I27-1 -> -0.36677815 | L27: =F27/J27-1 -> 0.16155419
B29: DLF — KEY METRICS
B30: 52-Week High | C30: =MAX(D16:D27) -> 897
B31: 52-Week Low | C31: =MIN(E16:E27) -> 489
B32: All-Period High | C32: =MAX(D7:D27) -> 935
B33: All-Period Low | C33: =MIN(E7:E27) -> 325
B34: Current Price | C34: =F27 -> 568
B35: % Off All-Period High | C35: =F27/MAX(D7:D27)-1 -> -0.39251337
B36: Average Monthly Volume (Lakh) | C36: =AVERAGE(G7:G27) -> 652.85714
B37: Average Monthly Return | C37: =AVERAGE(H8:H27) -> 0.026193195
B38: Monthly Return Volatility (σ) | C38: =STDEV(H8:H27) -> 0.12991497
B39: Annualised Volatility (σ×√12) | C39: =STDEV(H8:H27)*SQRT(12) -> 0.45003865
B40: 4-Year Total Return | C40: =F27/F7-1 -> 0.43797468
B41: 4-Year CAGR (approx) | C41: =(F27/F7)^(1/4)-1 -> 0.095059734
B79: DLF — KEY EVENTS DRIVING PRICE MOVEMENTS
B80: Date | C80: Event | I80: Price Impact
...

Sheet DCF
B2: AWFIS — DCF VALUATION (FCFF APPROACH)
B3: 5-Year Forecast + Terminal Value | ₹ Crores
B5: WACC | C5: =Assumptions!C37 -> 0.123676
B6: Terminal Growth (g) | C6: =Assumptions!C48 -> 0.05
B7: Tax Rate | C7: =Assumptions!C33 -> 0.252
B9: Particulars | C9: FY27E | D9: FY28E | E9: FY29E | F9: FY30E | G9: FY31E
B10: Revenue | C10: =Target_Financials!G7 -> 1920 | D10: =Target_Financials!H7 -> 2381 | E10: =Target_Financials!I7 -> 2857 | F10: =E10*(1+Assumptions!C42) -> 3314.12 | G10: =F10*(1+Assumptions!C43) -> 3711.8144
B11: Growth % | C11: =C10/Target_Financials!F7-1 -> 0.28 | D11: =D10/C10-1 -> 0.24010417 | E11: =E10/D10-1 -> 0.199916 | F11: =F10/E10-1 -> 0.16 | G11: =G10/F10-1 -> 0.12
B12: EBITDA | C12: =C10*Assumptions!$C$44 -> 537.6 | D12: =D10*Assumptions!$C$44 -> 666.68 | E12: =E10*Assumptions!$C$44 -> 799.96 | F12: =F10*Assumptions!$C$44 -> 927.9536 | G12: =G10*Assumptions!$C$44 -> 1039.308
B13: (-) D&A | C13: =C10*Assumptions!$C$45 -> 422.4 | D13: =D10*Assumptions!$C$45 -> 523.82 | E13: =E10*Assumptions!$C$45 -> 628.54 | F13: =F10*Assumptions!$C$45 -> 729.1064 | G13: =G10*Assumptions!$C$45 -> 816.59917
B14: EBIT | C14: =C12-C13 -> 115.2 | D14: =D12-D13 -> 142.86 | E14: =E12-E13 -> 171.42 | F14: =F12-F13 -> 198.8472 | G14: =G12-G13 -> 222.70886
B15: (-) Tax on EBIT | C15: =MAX(C14*$C$7,0) -> 29.0304 | D15: =MAX(D14*$C$7,0) -> 36.00072 | E15: =MAX(E14*$C$7,0) -> 43.19784 | F15: =MAX(F14*$C$7,0) -> 50.109494 | G15: =MAX(G14*$C$7,0) -> 56.122634
B16: NOPAT | C16: =C14-C15 -> 86.1696 | D16: =D14-D15 -> 106.85928 | E16: =E14-E15 -> 128.22216 | F16: =F14-F15 -> 148.73771 | G16: =G14-G15 -> 166.58623
B17: (+) D&A | C17: =C13 -> 422.4 | D17: =D13 -> 523.82 | E17: =E13 -> 628.54 | F17: =F13 -> 729.1064 | G17: =G13 -> 816.59917
B18: (-) CapEx | C18: =C10*Assumptions!$C$46 -> 230.4 | D18: =D10*Assumptions!$C$46 -> 285.72 | E18: =E10*Assumptions!$C$46 -> 342.84 | F18: =F10*Assumptions!$C$46 -> 397.6944 | G18: =G10*Assumptions!$C$46 -> 445.41773
B19: (-) Δ Working Capital | C19: =(C10-Target_Financials!F7)*Assumptions!$C$47 -> 21 | D19: =(D10-C10)*Assumptions!$C$47 -> 23.05 | E19: =(E10-D10)*Assumptions!$C$47 -> 23.8 | F19: =(F10-E10)*Assumptions!$C$47 -> 22.856 | G19: =(G10-F10)*Assumptions!$C$47 -> 19.88472
B20: Free Cash Flow to Firm (FCFF) | C20: =C16+C17-C18-C19 -> 257.1696 | D20: =D16+D17-D18-D19 -> 321.90928 | E20: =E16+E17-E18-E19 -> 390.12216 | F20: =F16+F17-F18-F19 -> 457.29371 | G20: =G16+G17-G18-G19 -> 517.88295
B21: Discount Period | C21: 1 | D21: 2 | E21: 3 | F21: 4 | G21: 5
B22: Discount Factor | C22: =1/(1+$C$5)^C21 -> 0.88993624 | D22: =1/(1+$C$5)^D21 -> 0.79198652 | E22: =1/(1+$C$5)^E21 -> 0.70481751 | F22: =1/(1+$C$5)^F21 -> 0.62724265 | G22: =1/(1+$C$5)^G21 -> 0.55820597
B23: PV of FCFF | C23: =C20*C22 -> 228.86455 | D23: =D20*D22 -> 254.94781 | E23: =E20*E22 -> 274.96493 | F23: =F20*F22 -> 286.83411 | G23: =G20*G22 -> 289.08535
B26: TERMINAL VALUE (Gordon Growth)
B27: FY31E FCFF × (1+g) | C27: =G20*(1+C6) -> 543.7771
B28: Terminal Value (end of FY31E) | C28: =C27/(C5-C6) -> 7380.6545
B29: PV of Terminal Value | C29: =C28*G22 -> 4119.9254
B32: ENTERPRISE VALUE SUMMARY
B33: Sum of PV of Explicit FCFF | C33: =SUM(C23:G23) -> 1334.6968
B34: (+) PV of Terminal Value | C34: =C29 -> 4119.9254
B35: Enterprise Value (Base Case) | C35: =C33+C34 -> 5454.6221
B36: (-) Net Debt (FY26E) | C36: =Assumptions!C20 -> 1160
B37: Equity Value | C37: =C35-C36 -> 4294.6221
B38: Implied Value per Share (₹) | C38: =C37/Assumptions!C18 -> 596.47529
B41: DCF SENSITIVITY — Implied Value per Share (₹)
B42: WACC ↓ / g → | C42: 0.035 | D42: 0.04 | E42: 0.045 | F42: 0.05 | G42: 0.055 | H42: 0.06
B43: 0.1 | C43: =((C$20/(1+$B43)^1+D$20/(1+$B43)^2+E$20/(1+$B43)^3+F$20/(1+$B43)^4+G$20/(1+$B43)^5)+(G$20*(1+C$42)/($B43-C$42))/(1+$B43)^5-Assumptions!$C$20)/Assumptions!$C$18 -> 748.21326 | D43: =((C$20/(1+$B43)^1+D$20/(1+$B43)^2+E$20/(1+$B43)^3+F$20/(1+$B43)^4+G$20/(1+$B43)^5)+(G$20*(1+D$42)/($B43-D$42))/(1+$B43)^5-Assumptions!$C$20)/Assumptions!$C$18 -> 811.19777 | E43: =((C$20/(1+$B43)^1+D$20/(1+$B43)^2+E$20/(1+$B43)^3+F$20/(1+$B43)^4+G$20/(1+$B43)^5)+(G$20*(1+E$42)/($B43-E$42))/(1+$B43)^5-Assumptions!$C$20)/Assumptions!$C$18 -> 885.63402 | F43: =((C$20/(1+$B43)^1+D$20/(1+$B43)^2+E$20/(1+$B43)^3+F$20/(1+$B43)^4+G$20/(1+$B43)^5)+(G$20*(1+F$42)/($B43-F$42))/(1+$B43)^5-Assumptions!$C$20)/Assumptions!$C$18 -> 974.95751 | G43: =((C$20/(1+$B43)^1+D$20/(1+$B43)^2+E$20/(1+$B43)^3+F$20/(1+$B43)^4+G$20/(1+$B43)^5)+(G$20*(1+G$42)/($B43-G$42))/(1+$B43)^5-Assumptions!$C$20)/Assumptions!$C$18 -> 1084.1307 | H43: =((C$20/(1+$B43)^1+D$20/(1+$B43)^2+E$20/(1+$B43)^3+F$20/(1+$B43)^4+G$20/(1+$B43)^5)+(G$20*(1+H$42)/($B43-H$42))/(1+$B43)^5-Assumptions!$C$20)/Assumptions!$C$18 -> 1220.5971
B44: 0.11 | C44: =((C$20/(1+$B44)^1+D$20/(1+$B44)^2+E$20/(1+$B44)^3+F$20/(1+$B44)^4+G$20/(1+$B44)^5)+(G$20*(1+C$42)/($B44-C$42))/(1+$B44)^5-Assumptions!$C$20)/Assumptions!$C$18 -> 620.5622 | D44: =((C$20/(1+$B44)^1+D$20/(1+$B44)^2+E$20/(1+$B44)^3+F$20/(1+$B44)^4+G$20/(1+$B44)^5)+(G$20*(1+D$42)/($B44-D$42))/(1+$B44)^5-Assumptions!$C$20)/Assumptions!$C$18 -> 665.68727 | E44: =((C$20/(1+$B44)^1+D$20/(1+$B44)^2+E$20/(1+$B44)^3+F$20/(1+$B44)^4+G$20/(1+$B44)^5)+(G$20*(1+E$42)/($B44-E$42))/(1+$B44)^5-Assumptions!$C$20)/Assumptions!$C$18 -> 717.75466 | F44: =((C$20/(1+$B44)^1+D$20/(1+$B44)^2+E$20/(1+$B44)^3+F$20/(1+$B44)^4+G$20/(1+$B44)^5)+(G$20*(1+F$42)/($B44-F$42))/(1+$B44)^5-Assumptions!$C$20)/Assumptions!$C$18 -> 778.49995 | G44: =((C$20/(1+$B44)^1+D$20/(1+$B44)^2+E$20/(1+$B44)^3+F$20/(1+$B44)^4+G$20/(1+$B44)^5)+(G$20*(1+G$42)/($B44-G$42))/(1+$B44)^5-Assumptions!$C$20)/Assumptions!$C$18 -> 850.28983 | H44: =((C$20/(1+$B44)^1+D$20/(1+$B44)^2+E$20/(1+$B44)^3+F$20/(1+$B44)^4+G$20/(1+$B44)^5)+(G$20*(1+H$42)/($B44-H$42))/(1+$B44)^5-Assumptions!$C$20)/Assumptions!$C$18 -> 936.4377
B45: 0.12 | C45: =((C$20/(1+$B45)^1+D$20/(1+$B45)^2+E$20/(1+$B45)^3+F$20/(1+$B45)^4+G$20/(1+$B45)^5)+(G$20*(1+C$42)/($B45-C$42))/(1+$B45)^5-Assumptions!$C$20)/Assumptions!$C$18 -> 523.13698 | D45: =((C$20/(1+$B45)^1+D$20/(1+$B45)^2+E$20/(1+$B45)^3+F$20/(1+$B45)^4+G$20/(1+$B45)^5)+(G$20*(1+D$42)/($B45-D$42))/(1+$B45)^5-Assumptions!$C$20)/Assumptions!$C$18 -> 556.7485 | E45: =((C$20/(1+$B45)^1+D$20/(1+$B45)^2+E$20/(1+$B45)^3+F$20/(1+$B45)^4+G$20/(1+$B45)^5)+(G$20*(1+E$42)/($B45-E$42))/(1+$B45)^5-Assumptions!$C$20)/Assumptions!$C$18 -> 594.84155 | F45: =((C$20/(1+$B45)^1+D$20/(1+$B45)^2+E$20/(1+$B45)^3+F$20/(1+$B45)^4+G$20/(1+$B45)^5)+(G$20*(1+F$42)/($B45-F$42))/(1+$B45)^5-Assumptions!$C$20)/Assumptions!$C$18 -> 638.37647 | G45: =((C$20/(1+$B45)^1+D$20/(1+$B45)^2+E$20/(1+$B45)^3+F$20/(1+$B45)^4+G$20/(1+$B45)^5)+(G$20*(1+G$42)/($B45-G$42))/(1+$B45)^5-Assumptions!$C$20)/Assumptions!$C$18 -> 688.60907 | H45: =((C$20/(1+$B45)^1+D$20/(1+$B45)^2+E$20/(1+$B45)^3+F$20/(1+$B45)^4+G$20/(1+$B45)^5)+(G$20*(1+H$42)/($B45-H$42))/(1+$B45)^5-Assumptions!$C$20)/Assumptions!$C$18 -> 747.21377
B46: 0.13 | C46: =((C$20/(1+$B46)^1+D$20/(1+$B46)^2+E$20/(1+$B46)^3+F$20/(1+$B46)^4+G$20/(1+$B46)^5)+(G$20*(1+C$42)/($B46-C$42))/(1+$B46)^5-Assumptions!$C$20)/Assumptions!$C$18 -> 446.38504 | D46: =((C$20/(1+$B46)^1+D$20/(1+$B46)^2+E$20/(1+$B46)^3+F$20/(1+$B46)^4+G$20/(1+$B46)^5)+(G$20*(1+D$42)/($B46-D$42))/(1+$B46)^5-Assumptions!$C$20)/Assumptions!$C$18 -> 472.18323 | E46: =((C$20/(1+$B46)^1+D$20/(1+$B46)^2+E$20/(1+$B46)^3+F$20/(1+$B46)^4+G$20/(1+$B46)^5)+(G$20*(1+E$42)/($B46-E$42))/(1+$B46)^5-Assumptions!$C$20)/Assumptions!$C$18 -> 501.0165 | F46: =((C$20/(1+$B46)^1+D$20/(1+$B46)^2+E$20/(1+$B46)^3+F$20/(1+$B46)^4+G$20/(1+$B46)^5)+(G$20*(1+F$42)/($B46-F$42))/(1+$B46)^5-Assumptions!$C$20)/Assumptions!$C$18 -> 533.45393 | G46: =((C$20/(1+$B46)^1+D$20/(1+$B46)^2+E$20/(1+$B46)^3+F$20/(1+$B46)^4+G$20/(1+$B46)^5)+(G$20*(1+G$42)/($B46-G$42))/(1+$B46)^5-Assumptions!$C$20)/Assumptions!$C$18 -> 570.21635 | H46: =((C$20/(1+$B46)^1+D$20/(1+$B46)^2+E$20/(1+$B46)^3+F$20/(1+$B46)^4+G$20/(1+$B46)^5)+(G$20*(1+H$42)/($B46-H$42))/(1+$B46)^5-Assumptions!$C$20)/Assumptions!$C$18 -> 612.23055
B47: 0.14 | C47: =((C$20/(1+$B47)^1+D$20/(1+$B47)^2+E$20/(1+$B47)^3+F$20/(1+$B47)^4+G$20/(1+$B47)^5)+(G$20*(1+C$42)/($B47-C$42))/(1+$B47)^5-Assumptions!$C$20)/Assumptions!$C$18 -> 384.39325 | D47: =((C$20/(1+$B47)^1+D$20/(1+$B47)^2+E$20/(1+$B47)^3+F$20/(1+$B47)^4+G$20/(1+$B47)^5)+(G$20*(1+D$42)/($B47-D$42))/(1+$B47)^5-Assumptions!$C$20)/Assumptions!$C$18 -> 404.6729 | E47: =((C$20/(1+$B47)^1+D$20/(1+$B47)^2+E$20/(1+$B47)^3+F$20/(1+$B47)^4+G$20/(1+$B47)^5)+(G$20*(1+E$42)/($B47-E$42))/(1+$B47)^5-Assumptions!$C$20)/Assumptions!$C$18 -> 427.08724 | F47: =((C$20/(1+$B47)^1+D$20/(1+$B47)^2+E$20/(1+$B47)^3+F$20/(1+$B47)^4+G$20/(1+$B47)^5)+(G$20*(1+F$42)/($B47-F$42))/(1+$B47)^5-Assumptions!$C$20)/Assumptions!$C$18 -> 451.99207 | G47: =((C$20/(1+$B47)^1+D$20/(1+$B47)^2+E$20/(1+$B47)^3+F$20/(1+$B47)^4+G$20/(1+$B47)^5)+(G$20*(1+G$42)/($B47-G$42))/(1+$B47)^5-Assumptions!$C$20)/Assumptions!$C$18 -> 479.82689 | H47: =((C$20/(1+$B47)^1+D$20/(1+$B47)^2+E$20/(1+$B47)^3+F$20/(1+$B47)^4+G$20/(1+$B47)^5)+(G$20*(1+H$42)/($B47-H$42))/(1+$B47)^5-Assumptions!$C$20)/Assumptions!$C$18 -> 511.14105
B50: DCF VALUE RANGE (for Football Field)
B51: Low | C51: =C47 -> 384.39325
...

Sheet Trading_Comps
B2: TRADING COMPARABLES ANALYSIS
B3: Listed flex-workspace & commercial real estate peers | ₹ Crores
B5: Company | C5: Mkt Cap | D5: Net Debt | E5: EV | F5: Revenue | G5: EBITDA | H5: EV/Rev | I5: EV/EBITDA | J5: P/E
B6: IWG plc (UK, $GBP) | C6: 15500 | D6: 45000 | E6: =C6+D6 -> 60500 | F6: 32500 | G6: 5200 | H6: =E6/F6 -> 1.8615385 | I6: =E6/G6 -> 11.634615 | J6: 28
B7: WeWork Inc. (post-emerge) | C7: 1800 | D7: 9500 | E7: =C7+D7 -> 11300 | F7: 6200 | G7: 1100 | H7: =E7/F7 -> 1.8225806 | I7: =E7/G7 -> 10.272727 | J7: N/M
B8: Embassy Office Parks REIT | C8: 33500 | D8: 19500 | E8: =C8+D8 -> 53000 | F8: 3850 | G8: 3100 | H8: =E8/F8 -> 13.766234 | I8: =E8/G8 -> 17.096774 | J8: 22.5
B9: Mindspace Business Parks REIT | C9: 22000 | D9: 12500 | E9: =C9+D9 -> 34500 | F9: 2650 | G9: 2050 | H9: =E9/F9 -> 13.018868 | I9: =E9/G9 -> 16.829268 | J9: 20
B10: Nexus Select Trust | C10: 20500 | D10: 10500 | E10: =C10+D10 -> 31000 | F10: 2450 | G10: 1700 | H10: =E10/F10 -> 12.653061 | I10: =E10/G10 -> 18.235294 | J10: 24
B11: Prestige Estates Projects | C11: 67500 | D11: 18500 | E11: =C11+D11 -> 86000 | F11: 11500 | G11: 3200 | H11: =E11/F11 -> 7.4782609 | I11: =E11/G11 -> 26.875 | J11: 32
B12: Phoenix Mills | C12: 47500 | D12: 6800 | E12: =C12+D12 -> 54300 | F12: 4100 | G12: 2350 | H12: =E12/F12 -> 13.243902 | I12: =E12/G12 -> 23.106383 | J12: 35
B13: Brookfield India REIT | C13: 14500 | D13: 11500 | E13: =C13+D13 -> 26000 | F13: 1950 | G13: 1400 | H13: =E13/F13 -> 13.333333 | I13: =E13/G13 -> 18.571429 | J13: 21
B15: Minimum | H15: =MIN(H6:H13) -> 1.8225806 | I15: =MIN(I6:I13) -> 10.272727
B16: 25th Percentile | H16: =PERCENTILE(H6:H13,0.25) -> 6.0740803 | I16: =PERCENTILE(I6:I13,0.25) -> 15.530605
B17: Median | H17: =MEDIAN(H6:H13) -> 12.835965 | I17: =MEDIAN(I6:I13) -> 17.666034
B18: Mean | H18: =AVERAGE(H6:H13) -> 9.6472223 | I18: =AVERAGE(I6:I13) -> 17.827686
B19: 75th Percentile | H19: =PERCENTILE(H6:H13,0.75) -> 13.26626 | I19: =PERCENTILE(I6:I13,0.75) -> 19.705167
B20: Maximum | H20: =MAX(H6:H13) -> 13.766234 | I20: =MAX(I6:I13) -> 26.875
B23: APPLICATION TO AWFIS — Implied Valuation
B24: Awfis FY26E EBITDA (₹ Cr) | C24: =Target_Financials!F9 -> 510
B25: Awfis Net Debt (₹ Cr) | C25: =Assumptions!C20 -> 1160
B26: Awfis Diluted Shares (Cr) | C26: =Assumptions!C18 -> 7.2
B28: Scenario | C28: Multiple (EV/EBITDA) | D28: Implied EV | E28: Implied Equity | F28: Implied Price (₹)
B29: Low (25th pct) | C29: =I16 -> 15.530605 | D29: =C29*C24 -> 7920.6086 | E29: =D29-C25 -> 6760.6086 | F29: =E29/C26 -> 938.97341
B30: Mid (Median) | C30: =I17 -> 17.666034 | D30: =C30*C24 -> 9009.6774 | E30: =D30-C25 -> 7849.6774 | F30: =E30/C26 -> 1090.233
B31: High (75th pct) | C31: =I19 -> 19.705167 | D31: =C31*C24 -> 10049.635 | E31: =D31-C25 -> 8889.6353 | F31: =E31/C26 -> 1234.6716
B33: Source: Screener.in, NSE/BSE filings, Q3 FY26 results, investor presentations. All figures approximate for illustrative academic use.

Sheet Precedent_Transactions
B2: PRECEDENT TRANSACTIONS ANALYSIS
B3: Recent M&A deals in flex-workspace / commercial real estate | ₹ Crores
B5: Target | C5: Acquirer | D5: Year | E5: Deal Value | F5: Target Rev | G5: Target EBITDA | H5: EV/Rev | I5: EV/EBITDA
B6: Smartworks (stake) | C6: TPG/Keppel | D6: 2024 | E6: 3200 | F6: 800 | G6: 220 | H6: =E6/F6 -> 4 | I6: =E6/G6 -> 14.545455
B7: Table Space | C7: Hillhouse Capital | D7: 2023 | E7: 2800 | F7: 650 | G7: 180 | H7: =E7/F7 -> 4.3076923 | I7: =E7/G7 -> 15.555556
B8: WeWork India (stake) | C8: Embassy Group | D8: 2024 | E8: 4500 | F8: 1650 | G8: 450 | H8: =E8/F8 -> 2.7272727 | I8: =E8/G8 -> 10
B9: Indiqube | C9: MPL/Westbridge | D9: 2023 | E9: 1800 | F9: 480 | G9: 130 | H9: =E9/F9 -> 3.75 | I9: =E9/G9 -> 13.846154
B10: 91Springboard | C10: Investor consortium | D10: 2022 | E10: 900 | F10: 260 | G10: 65 | H10: =E10/F10 -> 3.4615385 | I10: =E10/G10 -> 13.846154
B11: The Executive Centre | C11: HPEF | D11: 2024 | E11: 6500 | F11: 1800 | G11: 480 | H11: =E11/F11 -> 3.6111111 | I11: =E11/G11 -> 13.541667
B12: Spaces (pan-India) | C12: IWG expansion | D12: 2023 | E12: 2100 | F12: 540 | G12: 155 | H12: =E12/F12 -> 3.8888889 | I12: =E12/G12 -> 13.548387
B13: Simpliwork Offices | C13: Actis | D13: 2022 | E13: 1400 | F13: 380 | G13: 110 | H13: =E13/F13 -> 3.6842105 | I13: =E13/G13 -> 12.727273
B15: Minimum | H15: =MIN(H6:H13) -> 2.7272727 | I15: =MIN(I6:I13) -> 10
B16: 25th Percentile | H16: =PERCENTILE(H6:H13,0.25) -> 3.5737179 | I16: =PERCENTILE(I6:I13,0.25) -> 13.338068
B17: Median | H17: =MEDIAN(H6:H13) -> 3.7171053 | I17: =MEDIAN(I6:I13) -> 13.69727
B18: Mean | H18: =AVERAGE(H6:H13) -> 3.6788393 | I18: =AVERAGE(I6:I13) -> 13.451331
B19: 75th Percentile | H19: =PERCENTILE(H6:H13,0.75) -> 3.9166667 | I19: =PERCENTILE(I6:I13,0.75) -> 14.020979
B20: Maximum | H20: =MAX(H6:H13) -> 4.3076923 | I20: =MAX(I6:I13) -> 15.555556
B23: APPLICATION TO AWFIS — Implied Valuation
B24: Awfis FY26E EBITDA (₹ Cr) | C24: =Target_Financials!F9 -> 510
B25: Awfis Net Debt (₹ Cr) | C25: =Assumptions!C20 -> 1160
B26: Awfis Diluted Shares (Cr) | C26: =Assumptions!C18 -> 7.2
B28: Scenario | C28: Multiple (EV/EBITDA) | D28: Implied EV | E28: Implied Equity | F28: Implied Price (₹)
B29: Low (25th pct) | C29: =I16 -> 13.338068 | D29: =C29*C24 -> 6802.4148 | E29: =D29-C25 -> 5642.4148 | F29: =E29/C26 -> 783.66872
B30: Mid (Median) | C30: =I17 -> 13.69727 | D30: =C30*C24 -> 6985.6079 | E30: =D30-C25 -> 5825.6079 | F30: =E30/C26 -> 809.11221
B31: High (75th pct) | C31: =I19 -> 14.020979 | D31: =C31*C24 -> 7150.6993 | E31: =D31-C25 -> 5990.6993 | F31: =E31/C26 -> 832.04157
B33: Note: Transaction values illustrative for academic use; precedents include control premia (20–35% typical).

Sheet Football_Field
B2: FOOTBALL FIELD — VALUATION RANGE SUMMARY
B3: Awfis Implied Value per Share (₹) across methodologies
B5: Methodology | C5: Low (₹) | D5: High (₹) | E5: Width (for chart) | F5: Midpoint (₹)
B6: 52-Week Trading Range | C6: =Assumptions!C23 -> 320.7 | D6: =Assumptions!C22 -> 718.95 | E6: =D6-C6 -> 398.25 | F6: =(C6+D6)/2 -> 519.825
B7: DCF (Sensitized) | C7: =DCF!C51 -> 384.39325 | D7: =DCF!C53 -> 1220.5971 | E7: =D7-C7 -> 836.20386 | F7: =(C7+D7)/2 -> 802.49518
B8: Trading Comparables | C8: =Trading_Comps!F29 -> 938.97341 | D8: =Trading_Comps!F31 -> 1234.6716 | E8: =D8-C8 -> 295.69815 | F8: =(C8+D8)/2 -> 1086.8225
B9: Precedent Transactions | C9: =Precedent_Transactions!F29 -> 783.66872 | D9: =Precedent_Transactions!F31 -> 832.04157 | E9: =D9-C9 -> 48.372851 | F9: =(C9+D9)/2 -> 807.85514
B10: Current Market Price (CMP) | C10: =Assumptions!C17 -> 331.05 | D10: =Assumptions!C17 -> 331.05 | E10: =D10-C10 -> 0 | F10: =(C10+D10)/2 -> 331.05
B12: Proposed Offer Price | C12: =Assumptions!C51 -> 475 | D12: =Assumptions!C51 -> 475 | E12: =D12-C12 -> 0 | F12: =C12 -> 475
B14: Premium to CMP | C14: =C12/Assumptions!C17-1 -> 0.43482858
B40: KEY OBSERVATIONS
B41: • The proposed offer price of ₹475 sits at the conservative end of the valuation range,
B42: below DCF mid-case (~₹596) and well below trading comps (~₹939–1,234).
B43: • Precedent transactions imply ₹784–832, embedding 20–35% control premia — supports the offer.
B44: • At ₹475, offer represents ~43% premium to Awfis CMP of ₹331 — in line with Indian M&A norms (30–40%).
B45: • The overlap zone across DCF, Precedents, and Trading Comps bounds is approximately ₹596–832,
B46: suggesting a defensible negotiating ceiling of ~₹800 if competitive bidding emerges.

Sheet Accretion_Dilution
B2: EPS ACCRETION / DILUTION — 6 FINANCING MIX SCENARIOS
B3: Pro forma DLF EPS impact across combinations of Cash, Debt, and Stock | ₹ Crores
B5: DEAL INPUTS (from Assumptions)
B6: Offer Price per Awfis Share (₹) | C6: =Assumptions!C51 -> 475
B7: Awfis Diluted Shares (Cr) | C7: =Assumptions!C18 -> 7.2
B8: Equity Consideration (₹ Cr) | C8: =Assumptions!C53 -> 3420
B9: Awfis Net Debt Assumed (₹ Cr) | C9: =Assumptions!C54 -> 1160
B10: Total Purchase Price incl. Debt | C10: =Assumptions!C55 -> 4580
B11: DLF CMP (₹) | C11: =Assumptions!C7 -> 568.25
B12: DLF Diluted Shares (Cr) | C12: =Assumptions!C8 -> 247.5
B13: New Debt Interest Rate | C13: =Assumptions!C61 -> 0.0875
B14: Foregone Yield on Balance-Sheet Cash | C14: 0.06
B15: DLF Tax Rate | C15: =Assumptions!C62 -> 0.252
B17: STANDALONE FY27E FINANCIALS
B18: Item | C18: DLF | D18: Awfis | E18: Combined (pre-adj)
B19: Revenue (FY27E) | C19: =Acquirer_Financials!G7 -> 12960 | D19: =Target_Financials!G7 -> 1920 | E19: =C19+D19 -> 14880
B20: EBITDA (FY27E) | C20: =Acquirer_Financials!G9 -> 5313 | D20: =Target_Financials!G9 -> 653 | E20: =C20+D20 -> 5966
B21: PAT (FY27E) | C21: =Acquirer_Financials!G17 -> 4131.204 | D21: =Target_Financials!G17 -> 94.248 | E21: =C21+D21 -> 4225.452
B22: DLF Standalone EPS (₹) | C22: =Acquirer_Financials!G19 -> 16.691733
B24: SYNERGIES (FY27E — Year 1 phase-in 25%)
B25: Total Synergies (% of Target Rev) | C25: =Assumptions!C68 -> 0.1
B26: Run-rate Synergy (₹ Cr) | C26: =D19*C25 -> 192
B27: Year-1 Phase-in % | C27: =Assumptions!C69 -> 0.25
B28: Year-1 After-tax Synergy | C28: =C26*C27*(1-C15) -> 35.904
B29: Illustrative PPA D&A (after-tax, ₹ Cr) | C29: 50
B32: SCENARIO MATRIX — 6 FINANCING COMBINATIONS
B33: Scenario Name | C33: 1: All Cash (BS) | D33: 2: All Debt | E33: 3: All Stock | F33: 4: Cash + Debt (20/80) | G33: 5: Debt + Stock (50/50) | H33: 6: Mixed (10/40/50)
B34: % from Balance Sheet Cash | C34: 1 | D34: 0 | E34: 0 | F34: 0.2 | G34: 0 | H34: 0.1
B35: % from New Debt | C35: 0 | D35: 1 | E35: 0 | F35: 0.8 | G35: 0.5 | H35: 0.4
B36: % from Stock Issuance | C36: 0 | D36: 0 | E36: 1 | F36: 0 | G36: 0.5 | H36: 0.5
B37: Total (check = 100%) | C37: =C34+C35+C36 -> 1 | D37: =D34+D35+D36 -> 1 | E37: =E34+E35+E36 -> 1 | F37: =F34+F35+F36 -> 1 | G37: =G34+G35+G36 -> 1 | H37: =H34+H35+H36 -> 1
B39: CONSIDERATION BREAKDOWN (₹ Cr)
B40: Cash Used (₹ Cr) | C40: =$C$8*C34 -> 3420 | D40: =$C$8*D34 -> 0 | E40: =$C$8*E34 -> 0 | F40: =$C$8*F34 -> 684 | G40: =$C$8*G34 -> 0 | H40: =$C$8*H34 -> 342
B41: New Debt Raised (₹ Cr) | C41: =$C$8*C35 -> 0 | D41: =$C$8*D35 -> 3420 | E41: =$C$8*E35 -> 0 | F41: =$C$8*F35 -> 2736 | G41: =$C$8*G35 -> 1710 | H41: =$C$8*H35 -> 1368
B42: Stock Value (₹ Cr) | C42: =$C$8*C36 -> 0 | D42: =$C$8*D36 -> 0 | E42: =$C$8*E36 -> 3420 | F42: =$C$8*F36 -> 0 | G42: =$C$8*G36 -> 1710 | H42: =$C$8*H36 -> 1710
B43: New DLF Shares Issued (Cr) | C43: =C42/$C$11 -> 0 | D43: =D42/$C$11 -> 0 | E43: =E42/$C$11 -> 6.0184778 | F43: =F42/$C$11 -> 0 | G43: =G42/$C$11 -> 3.0092389 | H43: =H42/$C$11 -> 3.0092389
B45: PRO FORMA PAT BUILD (₹ Cr)
B46: DLF Standalone PAT | C46: =$C$21 -> 4131.204 | D46: =$C$21 -> 4131.204 | E46: =$C$21 -> 4131.204 | F46: =$C$21 -> 4131.204 | G46: =$C$21 -> 4131.204 | H46: =$C$21 -> 4131.204
B47: (+) Awfis PAT | C47: =$D$21 -> 94.248 | D47: =$D$21 -> 94.248 | E47: =$D$21 -> 94.248 | F47: =$D$21 -> 94.248 | G47: =$D$21 -> 94.248 | H47: =$D$21 -> 94.248
B48: (+) After-tax Synergies (Yr 1) | C48: =$C$28 -> 35.904 | D48: =$C$28 -> 35.904 | E48: =$C$28 -> 35.904 | F48: =$C$28 -> 35.904 | G48: =$C$28 -> 35.904 | H48: =$C$28 -> 35.904
...

Sheet Sensitivity
B2: SENSITIVITY ANALYSIS
B3: Year-1 EPS Accretion/(Dilution) — Offer Price × % Stock Mix (Scenario C)
B5: KEY CONSTANTS (pulled)
B6: Awfis Diluted Shares (Cr) | C6: =Assumptions!C18 -> 7.2
B7: DLF CMP (₹) | C7: =Assumptions!C7 -> 568.25
B8: DLF Diluted Shares (Cr) | C8: =Assumptions!C8 -> 247.5
B9: New Debt Interest Rate | C9: =Assumptions!C61 -> 0.0875
B10: DLF Tax Rate | C10: =Assumptions!C62 -> 0.252
B11: DLF Standalone PAT FY27E (₹ Cr) | C11: =Acquirer_Financials!G17 -> 4131.204
B12: Awfis PAT FY27E (₹ Cr) | C12: =Target_Financials!G17 -> 94.248
B13: After-tax Synergies Year 1 (₹ Cr) | C13: =Accretion_Dilution!C28 -> 35.904
B14: PPA D&A (after-tax) (₹ Cr) | C14: 50
B15: DLF Standalone EPS FY27E (₹) | C15: =Acquirer_Financials!G19 -> 16.691733
B18: TABLE 1 — EPS ACCRETION/(DILUTION) % | Offer Price ↓ / % Stock →
B19: Offer Price ↓ | C19: 0 | D19: 0.25 | E19: 0.5 | F19: 0.75 | G19: 1
B20: 400 | C20: =((($C$11+$C$12+$C$13-($B20*$C$6*(1-C$19))*$C$9*(1-$C$10)-$C$14)/($C$8+($B20*$C$6*C$19)/$C$7))/$C$15)-1 -> -0.026225769 | D20: =((($C$11+$C$12+$C$13-($B20*$C$6*(1-D$19))*$C$9*(1-$C$10)-$C$14)/($C$8+($B20*$C$6*D$19)/$C$7))/$C$15)-1 -> -0.019836758 | E20: =((($C$11+$C$12+$C$13-($B20*$C$6*(1-E$19))*$C$9*(1-$C$10)-$C$14)/($C$8+($B20*$C$6*E$19)/$C$7))/$C$15)-1 -> -0.0135125 | F20: =((($C$11+$C$12+$C$13-($B20*$C$6*(1-F$19))*$C$9*(1-$C$10)-$C$14)/($C$8+($B20*$C$6*F$19)/$C$7))/$C$15)-1 -> -0.0072520157 | G20: =((($C$11+$C$12+$C$13-($B20*$C$6*(1-G$19))*$C$9*(1-$C$10)-$C$14)/($C$8+($B20*$C$6*G$19)/$C$7))/$C$15)-1 -> -0.0010543445
B21: 450 | C21: =((($C$11+$C$12+$C$13-($B21*$C$6*(1-C$19))*$C$9*(1-$C$10)-$C$14)/($C$8+($B21*$C$6*C$19)/$C$7))/$C$15)-1 -> -0.031929191 | D21: =((($C$11+$C$12+$C$13-($B21*$C$6*(1-D$19))*$C$9*(1-$C$10)-$C$14)/($C$8+($B21*$C$6*D$19)/$C$7))/$C$15)-1 -> -0.024713467 | E21: =((($C$11+$C$12+$C$13-($B21*$C$6*(1-E$19))*$C$9*(1-$C$10)-$C$14)/($C$8+($B21*$C$6*E$19)/$C$7))/$C$15)-1 -> -0.017579913 | F21: =((($C$11+$C$12+$C$13-($B21*$C$6*(1-F$19))*$C$9*(1-$C$10)-$C$14)/($C$8+($B21*$C$6*F$19)/$C$7))/$C$15)-1 -> -0.010527131 | G21: =((($C$11+$C$12+$C$13-($B21*$C$6*(1-G$19))*$C$9*(1-$C$10)-$C$14)/($C$8+($B21*$C$6*G$19)/$C$7))/$C$15)-1 -> -0.0035537589
B22: 475 | C22: =((($C$11+$C$12+$C$13-($B22*$C$6*(1-C$19))*$C$9*(1-$C$10)-$C$14)/($C$8+($B22*$C$6*C$19)/$C$7))/$C$15)-1 -> -0.034780902 | D22: =((($C$11+$C$12+$C$13-($B22*$C$6*(1-D$19))*$C$9*(1-$C$10)-$C$14)/($C$8+($B22*$C$6*D$19)/$C$7))/$C$15)-1 -> -0.027149496 | E22: =((($C$11+$C$12+$C$13-($B22*$C$6*(1-E$19))*$C$9*(1-$C$10)-$C$14)/($C$8+($B22*$C$6*E$19)/$C$7))/$C$15)-1 -> -0.019609762 | F22: =((($C$11+$C$12+$C$13-($B22*$C$6*(1-F$19))*$C$9*(1-$C$10)-$C$14)/($C$8+($B22*$C$6*F$19)/$C$7))/$C$15)-1 -> -0.012160058 | G22: =((($C$11+$C$12+$C$13-($B22*$C$6*(1-G$19))*$C$9*(1-$C$10)-$C$14)/($C$8+($B22*$C$6*G$19)/$C$7))/$C$15)-1 -> -0.0047987817
B23: 500 | C23: =((($C$11+$C$12+$C$13-($B23*$C$6*(1-C$19))*$C$9*(1-$C$10)-$C$14)/($C$8+($B23*$C$6*C$19)/$C$7))/$C$15)-1 -> -0.037632613 | D23: =((($C$11+$C$12+$C$13-($B23*$C$6*(1-D$19))*$C$9*(1-$C$10)-$C$14)/($C$8+($B23*$C$6*D$19)/$C$7))/$C$15)-1 -> -0.029583975 | E23: =((($C$11+$C$12+$C$13-($B23*$C$6*(1-E$19))*$C$9*(1-$C$10)-$C$14)/($C$8+($B23*$C$6*E$19)/$C$7))/$C$15)-1 -> -0.021637046 | F23: =((($C$11+$C$12+$C$13-($B23*$C$6*(1-F$19))*$C$9*(1-$C$10)-$C$14)/($C$8+($B23*$C$6*F$19)/$C$7))/$C$15)-1 -> -0.013789909 | G23: =((($C$11+$C$12+$C$13-($B23*$C$6*(1-G$19))*$C$9*(1-$C$10)-$C$14)/($C$8+($B23*$C$6*G$19)/$C$7))/$C$15)-1 -> -0.0060406972
B24: 550 | C24: =((($C$11+$C$12+$C$13-($B24*$C$6*(1-C$19))*$C$9*(1-$C$10)-$C$14)/($C$8+($B24*$C$6*C$19)/$C$7))/$C$15)-1 -> -0.043336035 | D24: =((($C$11+$C$12+$C$13-($B24*$C$6*(1-D$19))*$C$9*(1-$C$10)-$C$14)/($C$8+($B24*$C$6*D$19)/$C$7))/$C$15)-1 -> -0.034448292 | E24: =((($C$11+$C$12+$C$13-($B24*$C$6*(1-E$19))*$C$9*(1-$C$10)-$C$14)/($C$8+($B24*$C$6*E$19)/$C$7))/$C$15)-1 -> -0.025683938 | F24: =((($C$11+$C$12+$C$13-($B24*$C$6*(1-F$19))*$C$9*(1-$C$10)-$C$14)/($C$8+($B24*$C$6*F$19)/$C$7))/$C$15)-1 -> -0.017040418 | G24: =((($C$11+$C$12+$C$13-($B24*$C$6*(1-G$19))*$C$9*(1-$C$10)-$C$14)/($C$8+($B24*$C$6*G$19)/$C$7))/$C$15)-1 -> -0.0085152526
B25: 600 | C25: =((($C$11+$C$12+$C$13-($B25*$C$6*(1-C$19))*$C$9*(1-$C$10)-$C$14)/($C$8+($B25*$C$6*C$19)/$C$7))/$C$15)-1 -> -0.049039457 | D25: =((($C$11+$C$12+$C$13-($B25*$C$6*(1-D$19))*$C$9*(1-$C$10)-$C$14)/($C$8+($B25*$C$6*D$19)/$C$7))/$C$15)-1 -> -0.039306432 | E25: =((($C$11+$C$12+$C$13-($B25*$C$6*(1-E$19))*$C$9*(1-$C$10)-$C$14)/($C$8+($B25*$C$6*E$19)/$C$7))/$C$15)-1 -> -0.029720627 | F25: =((($C$11+$C$12+$C$13-($B25*$C$6*(1-F$19))*$C$9*(1-$C$10)-$C$14)/($C$8+($B25*$C$6*F$19)/$C$7))/$C$15)-1 -> -0.020278728 | G25: =((($C$11+$C$12+$C$13-($B25*$C$6*(1-G$19))*$C$9*(1-$C$10)-$C$14)/($C$8+($B25*$C$6*G$19)/$C$7))/$C$15)-1 -> -0.010977517
B26: 650 | C26: =((($C$11+$C$12+$C$13-($B26*$C$6*(1-C$19))*$C$9*(1-$C$10)-$C$14)/($C$8+($B26*$C$6*C$19)/$C$7))/$C$15)-1 -> -0.054742879 | D26: =((($C$11+$C$12+$C$13-($B26*$C$6*(1-D$19))*$C$9*(1-$C$10)-$C$14)/($C$8+($B26*$C$6*D$19)/$C$7))/$C$15)-1 -> -0.044158405 | E26: =((($C$11+$C$12+$C$13-($B26*$C$6*(1-E$19))*$C$9*(1-$C$10)-$C$14)/($C$8+($B26*$C$6*E$19)/$C$7))/$C$15)-1 -> -0.033747154 | F26: =((($C$11+$C$12+$C$13-($B26*$C$6*(1-F$19))*$C$9*(1-$C$10)-$C$14)/($C$8+($B26*$C$6*F$19)/$C$7))/$C$15)-1 -> -0.023504907 | G26: =((($C$11+$C$12+$C$13-($B26*$C$6*(1-G$19))*$C$9*(1-$C$10)-$C$14)/($C$8+($B26*$C$6*G$19)/$C$7))/$C$15)-1 -> -0.013427583
B28: Interpretation: green = accretive, red = dilutive. All values are Year-1; synergies phase in 25% → 65% → 100% by Year 3.
B31: TABLE 2 — EPS ACCRETION/(DILUTION) % | Offer Price ↓ / Synergy Realization %
B32: Offer Price ↓ | C32: 0.5 | D32: 0.75 | E32: 1 | F32: 1.25 | G32: 1.5
B33: 400 | C33: =((($C$11+$C$12+$C$13*C$32-($B33*$C$6*0.5)*$C$9*(1-$C$10)-$C$14)/($C$8+($B33*$C$6*0.5)/$C$7))/$C$15)-1 -> -0.017813923 | D33: =((($C$11+$C$12+$C$13*D$32-($B33*$C$6*0.5)*$C$9*(1-$C$10)-$C$14)/($C$8+($B33*$C$6*0.5)/$C$7))/$C$15)-1 -> -0.015663212 | E33: =((($C$11+$C$12+$C$13*E$32-($B33*$C$6*0.5)*$C$9*(1-$C$10)-$C$14)/($C$8+($B33*$C$6*0.5)/$C$7))/$C$15)-1 -> -0.0135125 | F33: =((($C$11+$C$12+$C$13*F$32-($B33*$C$6*0.5)*$C$9*(1-$C$10)-$C$14)/($C$8+($B33*$C$6*0.5)/$C$7))/$C$15)-1 -> -0.011361789 | G33: =((($C$11+$C$12+$C$13*G$32-($B33*$C$6*0.5)*$C$9*(1-$C$10)-$C$14)/($C$8+($B33*$C$6*0.5)/$C$7))/$C$15)-1 -> -0.0092110772
B34: 450 | C34: =((($C$11+$C$12+$C$13*C$32-($B34*$C$6*0.5)*$C$9*(1-$C$10)-$C$14)/($C$8+($B34*$C$6*0.5)/$C$7))/$C$15)-1 -> -0.021875894 | D34: =((($C$11+$C$12+$C$13*D$32-($B34*$C$6*0.5)*$C$9*(1-$C$10)-$C$14)/($C$8+($B34*$C$6*0.5)/$C$7))/$C$15)-1 -> -0.019727903 | E34: =((($C$11+$C$12+$C$13*E$32-($B34*$C$6*0.5)*$C$9*(1-$C$10)-$C$14)/($C$8+($B34*$C$6*0.5)/$C$7))/$C$15)-1 -> -0.017579913 | F34: =((($C$11+$C$12+$C$13*F$32-($B34*$C$6*0.5)*$C$9*(1-$C$10)-$C$14)/($C$8+($B34*$C$6*0.5)/$C$7))/$C$15)-1 -> -0.015431923 | G34: =((($C$11+$C$12+$C$13*G$32-($B34*$C$6*0.5)*$C$9*(1-$C$10)-$C$14)/($C$8+($B34*$C$6*0.5)/$C$7))/$C$15)-1 -> -0.013283932
B35: 475 | C35: =((($C$11+$C$12+$C$13*C$32-($B35*$C$6*0.5)*$C$9*(1-$C$10)-$C$14)/($C$8+($B35*$C$6*0.5)/$C$7))/$C$15)-1 -> -0.023903026 | D35: =((($C$11+$C$12+$C$13*D$32-($B35*$C$6*0.5)*$C$9*(1-$C$10)-$C$14)/($C$8+($B35*$C$6*0.5)/$C$7))/$C$15)-1 -> -0.021756394 | E35: =((($C$11+$C$12+$C$13*E$32-($B35*$C$6*0.5)*$C$9*(1-$C$10)-$C$14)/($C$8+($B35*$C$6*0.5)/$C$7))/$C$15)-1 -> -0.019609762 | F35: =((($C$11+$C$12+$C$13*F$32-($B35*$C$6*0.5)*$C$9*(1-$C$10)-$C$14)/($C$8+($B35*$C$6*0.5)/$C$7))/$C$15)-1 -> -0.017463129 | G35: =((($C$11+$C$12+$C$13*G$32-($B35*$C$6*0.5)*$C$9*(1-$C$10)-$C$14)/($C$8+($B35*$C$6*0.5)/$C$7))/$C$15)-1 -> -0.015316497
B36: 500 | C36: =((($C$11+$C$12+$C$13*C$32-($B36*$C$6*0.5)*$C$9*(1-$C$10)-$C$14)/($C$8+($B36*$C$6*0.5)/$C$7))/$C$15)-1 -> -0.025927598 | D36: =((($C$11+$C$12+$C$13*D$32-($B36*$C$6*0.5)*$C$9*(1-$C$10)-$C$14)/($C$8+($B36*$C$6*0.5)/$C$7))/$C$15)-1 -> -0.023782322 | E36: =((($C$11+$C$12+$C$13*E$32-($B36*$C$6*0.5)*$C$9*(1-$C$10)-$C$14)/($C$8+($B36*$C$6*0.5)/$C$7))/$C$15)-1 -> -0.021637046 | F36: =((($C$11+$C$12+$C$13*F$32-($B36*$C$6*0.5)*$C$9*(1-$C$10)-$C$14)/($C$8+($B36*$C$6*0.5)/$C$7))/$C$15)-1 -> -0.01949177 | G36: =((($C$11+$C$12+$C$13*G$32-($B36*$C$6*0.5)*$C$9*(1-$C$10)-$C$14)/($C$8+($B36*$C$6*0.5)/$C$7))/$C$15)-1 -> -0.017346494
